{
 "cells": [
  {
   "cell_type": "code",
   "execution_count": 3,
   "metadata": {},
   "outputs": [],
   "source": [
    "from module.lastdance import Algorithm\n",
    "from module.jh import JH"
   ]
  },
  {
   "cell_type": "code",
   "execution_count": 4,
   "metadata": {},
   "outputs": [],
   "source": [
    "jh = JH()"
   ]
  },
  {
   "cell_type": "code",
   "execution_count": 5,
   "metadata": {},
   "outputs": [],
   "source": [
    "import pandas as pd \n",
    "from kiwipiepy import Kiwi\n",
    "import numpy as np\n",
    "import re\n",
    "import pickle"
   ]
  },
  {
   "cell_type": "code",
   "execution_count": 6,
   "metadata": {},
   "outputs": [],
   "source": [
    "with open(r\"module/nnp_list.pkl\", \"rb\") as r :\n",
    "    nnp_list = pickle.load(r)\n",
    "\n",
    "with open(r\"module/WD.StandardDict.p\", \"rb\") as r :\n",
    "    StandradDict = pickle.load(r)\n",
    "\n",
    "with open(r\"module/WD.WordToStandard.p\", \"rb\") as r :\n",
    "    WordToStandard = pickle.load(r)"
   ]
  },
  {
   "cell_type": "markdown",
   "metadata": {},
   "source": [
    "### Class process code re-factoring"
   ]
  },
  {
   "cell_type": "code",
   "execution_count": 7,
   "metadata": {},
   "outputs": [],
   "source": [
    "class Algorithm:\n",
    "    def __init__(self) -> None:\n",
    "        self.stop_words = [\"정식\",\"안주\"] \n",
    "        self.option_list = [\"추가\",\"선택\", \"많이\", \"적게\", \"조금\",\"빼고\", \"리필\",\"tall\",\"small\",\"large\",\"xl\",\"인분\",\"l\",\"m\",\"s\",\"grande\",\"venti\"\n",
    "                            \"reguler\", \"기본\"]\n",
    "\n",
    "\n",
    "    # stop words algorithm / Step 1 #\n",
    "    def is_stop_words(self, stop_word_text:str, stop_words_param:list) -> str:\n",
    "        \"\"\"_summary_\n",
    "\n",
    "        Args:\n",
    "            stop_word_text (str): _description_\n",
    "            stop_words_param (list): _description_\n",
    "\n",
    "        Returns:\n",
    "            str: _description_\n",
    "        \"\"\"\n",
    "        result = jh.kiwi.space(stop_word_text).split(\" \")\n",
    "        for i in result :\n",
    "            if i in stop_words_param :\n",
    "                pat = re.compile(f\"{i}\")\n",
    "                stop_word_text = re.sub(pat, \"\", stop_word_text)\n",
    "        return stop_word_text.strip()\n",
    "    # apply 선언 함수\n",
    "    stop_words_func = lambda self, txt : self.is_stop_words(txt, self.stop_words)\n",
    "    \n",
    "    # for bascket data algorithm / Step 2 #\n",
    "    def bascket_remove(self, text:str) -> str :\n",
    "        \"\"\"_summary_\n",
    "\n",
    "        Args:\n",
    "            text (str): _description_\n",
    "\n",
    "        Returns:\n",
    "            str: _description_\n",
    "        \"\"\"\n",
    "        pat = re.compile(r\"\\([^)]*\\)|\\[[^)]*\\]\")\n",
    "        pat2 = re.compile(r'\\(|\\)|\\[|\\]')\n",
    "        bascket_find = re.findall(pat, text)\n",
    "        if bascket_find : \n",
    "            res = [pat2.sub(\"\",i) for i in bascket_find ]\n",
    "            for i in res :\n",
    "                try : #  있는 경우 고유명사 검사\n",
    "                    if nnp_list[nnp_list.index(i)] :\n",
    "                        print(\"1\") \n",
    "                        try_pattern = re.compile(f\"\\({i}\\)|\\[{i}\\]\")\n",
    "                        sub_result = try_pattern.sub(\"\", text)  \n",
    "                    return \"\".join(sub_result)   \n",
    "                except : # 없는 경우 옵션 검사\n",
    "                    if i in self.option_list :\n",
    "                        print(i)\n",
    "                        except_pattern = re.compile(f\"\\({i}\\)|\\[{i}\\]\")\n",
    "                        except_sub_result = except_pattern.sub(\"\", text)\n",
    "                        print(except_sub_result)\n",
    "\n",
    "                    if except_sub_result :\n",
    "                        return \"\".join(except_sub_result)\n",
    "            return text\n",
    "\n",
    "    # option check algorithm / Step 3 #\n",
    "    def is_option(self, option_text:str, option_li:list) ->str:\n",
    "        \"\"\"_summary_\n",
    "\n",
    "        Args:\n",
    "            option_text (str): _description_\n",
    "            option_li (list): _description_\n",
    "\n",
    "        Returns:\n",
    "            str: _description_\n",
    "        \"\"\"\n",
    "        result = jh.kiwi.space(option_text).split(\" \")\n",
    "        for i in result :\n",
    "            if i in option_li :\n",
    "                pat = re.compile(f\"{i}\")\n",
    "                valiable = \"\".join(pat.findall(option_text))\n",
    "                return \" \".join(result), f\"옵션 {valiable}\"\n",
    "        else :\n",
    "            return option_text, \"\"\n",
    "    # apply 선언 함수\n",
    "    option_func = lambda self, txt : self.is_option(txt, self.option_list)\n",
    "\n",
    "    # special_character algorithm / Step 4 #\n",
    "    def special_char(self, special_text:str) -> str: \n",
    "        \"\"\"_summary_\n",
    "\n",
    "        Args:\n",
    "            special_text (str): _description_\n",
    "\n",
    "        Returns:\n",
    "            str: _description_\n",
    "        \"\"\"\n",
    "        split_result = re.split(r\"\\+|\\&|\\/|\\,\", special_text)\n",
    "        if len(split_result) >= 2 :\n",
    "            combine_text = [split_result[split_result.index(i)].strip() for i in split_result]\n",
    "            pattern = re.compile(r\"[^\\w\\s]+\")\n",
    "            return [pattern.sub(\"\", i ) for i in combine_text]\n",
    "        else : \n",
    "            pattern = re.compile(r\"[^\\w\\s]+\")\n",
    "            return pattern.sub(\"\", special_text)\n",
    "\n",
    "    # unit algorithm / Step 5 #\n",
    "    extract_morph = lambda self, x : jh.morph(x)\n",
    "\n",
    "    # space algorithm / Step 6 #\n",
    "    spacing_text = lambda self, x : jh.kiwi.space(x)\n",
    "\n",
    "    # remove_nnp/ Step 7 #\n",
    "    def nnp_extract(self, text:str, nnp_list:list) -> str :\n",
    "        \"\"\"_summary_\n",
    "\n",
    "        Args:\n",
    "            text (str): _description_\n",
    "            nnp_list (list): _description_\n",
    "\n",
    "        Returns:\n",
    "            str: _description_\n",
    "        \"\"\"\n",
    "        res = []\n",
    "        for i in text.split() :      \n",
    "            if i not in nnp_list :\n",
    "                res.append(i)\n",
    "        return \" \".join(res)\n",
    "\n",
    "    nnp_remove = lambda self, x: self.nnp_extract(x, nnp_list)\n",
    "\n",
    "\n",
    "    # std words / Step 8 #\n",
    "    def word_standard(self,txt:str) -> str :\n",
    "        \"\"\"_summary_\n",
    "\n",
    "        Args:\n",
    "            txt (str): _description_\n",
    "\n",
    "        Returns:\n",
    "            str: _description_\n",
    "        \"\"\"\n",
    "        res = []\n",
    "        for word in txt.split(' '):\n",
    "            try:\n",
    "                res.append(WordToStandard[word])\n",
    "            except :\n",
    "                res.append(word)\n",
    "        return \" \".join(res)\n",
    "        \n",
    "    # data standard / Step 9 #\n",
    "    def member_menu(self, txt:str) -> str :\n",
    "        \"\"\"_summary_\n",
    "\n",
    "        Args:\n",
    "            txt (str): _description_\n",
    "\n",
    "        Returns:\n",
    "            str: _description_\n",
    "        \"\"\"\n",
    "        score_ls = []\n",
    "        word_ls = txt.split(' ')\n",
    "        for word in word_ls:\n",
    "            try:\n",
    "                score_ls.append(StandradDict[word]['mean'])\n",
    "            except:\n",
    "                score_ls.append(10)\n",
    "        menu = word_ls[np.array(score_ls).argmin()]\n",
    "        word_ls.pop(word_ls.index(menu))\n",
    "        return word_ls, menu\n",
    "\n"
   ]
  },
  {
   "cell_type": "code",
   "execution_count": 8,
   "metadata": {},
   "outputs": [],
   "source": [
    "df = pd.read_excel(r\"C:\\Users\\user\\Desktop\\workbench\\dataset\\sampleTest.xlsx\")"
   ]
  },
  {
   "cell_type": "code",
   "execution_count": 17,
   "metadata": {},
   "outputs": [],
   "source": [
    "train = pd.read_excel(r\"C:\\Users\\user\\Desktop\\workbench\\dataset\\offerTrain.xlsx\")"
   ]
  },
  {
   "cell_type": "code",
   "execution_count": 9,
   "metadata": {},
   "outputs": [],
   "source": [
    "algo = Algorithm()"
   ]
  },
  {
   "attachments": {},
   "cell_type": "markdown",
   "metadata": {},
   "source": [
    "### 파이프라인 적용 할 프로세스형 함수"
   ]
  },
  {
   "cell_type": "code",
   "execution_count": 10,
   "metadata": {},
   "outputs": [],
   "source": [
    "def preprocessing(text) :\n",
    "    res = {'메뉴':None, '맛/재료':None, \n",
    "        '단위':None, '세트/옵션':None}\n",
    "        \n",
    "    x = algo.stop_words_func(text) # 불용어 알고리즘\n",
    "    # print(\"불용어 처리 알고리즘 : \", x)\n",
    "    x = algo.bascket_remove(x)\n",
    "    # print(\"괄호 처리 알고리즘 : \", x )\n",
    "    x = algo.option_func(x) # 옵션 알고리즘\n",
    "    # print(\"옵션 처리 알고리즘 : \", x)\n",
    "    if x[-1] : # 옵션 알고리즘을 통해 옵션 데이터로 판별 될 경우 함수 종료 \n",
    "        res[\"세트/옵션\"] = \"옵션\"\n",
    "        res[\"메뉴\"] = x[0]\n",
    "        return res\n",
    "    x = algo.special_char(x[0]) # 특수문자 알고리즘 \n",
    "    # print(\"특수문자 처리 알고리즘 :\", x)\n",
    "    if type(x) == list  : # (세트를 의미하는) 특수문자가 존재 하는 경우\n",
    "        res[\"세트/옵션\"] = \"세트\"\n",
    "        return res\n",
    "    rs = jh.morph(x)\n",
    "    print(rs)\n",
    "    # print(\"단위 처리 알고리즘 : \", rs )\n",
    "    try : \n",
    "        if rs[-1] :\n",
    "            res[\"단위\"] = \"\".join(rs[-1]) \n",
    "        x = algo.spacing_text(rs[0]) # 스페이싱 알고리즘\n",
    "    # print(\"스페이싱 알고리즘 : \", x )\n",
    "    except TypeError as e:\n",
    "        pass\n",
    "    x = algo.nnp_remove(x)\n",
    "    # print(\"고유명사 제거 알고리즘 : \", x)\n",
    "    x = algo.word_standard(x)\n",
    "    # print(\"단어 표준화 알고리즘 : \", x)\n",
    "    output = algo.member_menu(x)\n",
    "    # print(\"데이터 표준화 알고리즘 : \", output) \n",
    "    res[\"맛/재료\"] = \",\".join(output[0]); res[\"메뉴\"] = output[1]\n",
    "\n",
    "    ls = [i.form for i in jh.kiwi.tokenize(x) if i.tag[0] == \"N\"]\n",
    "\n",
    "    return {\"menu\" : \" \".join(ls),\n",
    "            \"std\" : res}\n"
   ]
  },
  {
   "cell_type": "code",
   "execution_count": 9,
   "metadata": {},
   "outputs": [],
   "source": [
    "from sklearn.pipeline import Pipeline"
   ]
  },
  {
   "cell_type": "code",
   "execution_count": 10,
   "metadata": {},
   "outputs": [
    {
     "ename": "TypeError",
     "evalue": "__init__() missing 1 required positional argument: 'steps'",
     "output_type": "error",
     "traceback": [
      "\u001b[1;31m---------------------------------------------------------------------------\u001b[0m",
      "\u001b[1;31mTypeError\u001b[0m                                 Traceback (most recent call last)",
      "\u001b[1;32m~\\AppData\\Local\\Temp\\ipykernel_9188\\601067689.py\u001b[0m in \u001b[0;36m<module>\u001b[1;34m\u001b[0m\n\u001b[1;32m----> 1\u001b[1;33m \u001b[0mpipeline\u001b[0m \u001b[1;33m=\u001b[0m \u001b[0mPipeline\u001b[0m\u001b[1;33m(\u001b[0m\u001b[1;33m)\u001b[0m\u001b[1;33m\u001b[0m\u001b[1;33m\u001b[0m\u001b[0m\n\u001b[0m",
      "\u001b[1;31mTypeError\u001b[0m: __init__() missing 1 required positional argument: 'steps'"
     ]
    }
   ],
   "source": [
    "pipeline = Pipeline([])"
   ]
  },
  {
   "cell_type": "code",
   "execution_count": 10,
   "metadata": {},
   "outputs": [
    {
     "name": "stderr",
     "output_type": "stream",
     "text": [
      "--- Logging error ---\n",
      "--- Logging error ---\n",
      "--- Logging error ---\n",
      "--- Logging error ---\n",
      "--- Logging error ---\n",
      "Error in sys.excepthook:\n",
      "Traceback (most recent call last):\n",
      "  File \"c:\\Users\\user\\anaconda3\\lib\\traceback.py\", line 495, in __init__\n",
      "    context = TracebackException(\n",
      "  File \"c:\\Users\\user\\anaconda3\\lib\\traceback.py\", line 495, in __init__\n",
      "    context = TracebackException(\n",
      "  File \"c:\\Users\\user\\anaconda3\\lib\\traceback.py\", line 495, in __init__\n",
      "    context = TracebackException(\n",
      "  [Previous line repeated 13 more times]\n",
      "  File \"c:\\Users\\user\\anaconda3\\lib\\traceback.py\", line 486, in __init__\n",
      "    exc_value.__cause__.__traceback__,\n",
      "AttributeError: 'str' object has no attribute '__traceback__'\n",
      "\n",
      "Original exception was:\n",
      "TypeError: print_exception(): Exception expected for value, str found\n",
      "\n",
      "The above exception was the direct cause of the following exception:\n",
      "\n",
      "Traceback (most recent call last):\n",
      "  File \"c:\\Users\\user\\anaconda3\\lib\\site-packages\\IPython\\core\\interactiveshell.py\", line 3457, in run_code\n",
      "    exec(code_obj, self.user_global_ns, self.user_ns)\n",
      "  File \"C:\\Users\\user\\AppData\\Local\\Temp\\ipykernel_16564\\2700920691.py\", line 1, in <module>\n",
      "  File \"C:\\Users\\user\\AppData\\Local\\Temp\\ipykernel_16564\\3657375467.py\", line 9, in preprocessing\n",
      "  File \"C:\\Users\\user\\AppData\\Local\\Temp\\ipykernel_16564\\3622754509.py\", line 81, in <lambda>\n",
      "  File \"C:\\Users\\user\\AppData\\Local\\Temp\\ipykernel_16564\\3622754509.py\", line 72, in is_option\n",
      "  File \"c:\\Users\\user\\anaconda3\\lib\\site-packages\\kiwipiepy\\_wrap.py\", line 1303, in space\n",
      "    return map(_space, super().analyze(text, 1, Match.ALL, echo=True))\n",
      "ValueError: `analyze` requires a `str` or an iterable of `str` parameters.\n",
      "\n",
      "During handling of the above exception, another exception occurred:\n",
      "\n",
      "Traceback (most recent call last):\n",
      "  File \"c:\\Users\\user\\anaconda3\\lib\\site-packages\\IPython\\core\\interactiveshell.py\", line 2077, in showtraceback\n",
      "    stb = value._render_traceback_()\n",
      "AttributeError: 'ValueError' object has no attribute '_render_traceback_'\n",
      "\n",
      "During handling of the above exception, another exception occurred:\n",
      "\n",
      "Traceback (most recent call last):\n",
      "  File \"c:\\Users\\user\\anaconda3\\lib\\site-packages\\IPython\\core\\interactiveshell.py\", line 3377, in run_ast_nodes\n",
      "    if (await self.run_code(code, result,  async_=asy)):\n",
      "  File \"c:\\Users\\user\\anaconda3\\lib\\site-packages\\IPython\\core\\interactiveshell.py\", line 3474, in run_code\n",
      "    self.showtraceback(running_compiled_code=True)\n",
      "  File \"c:\\Users\\user\\anaconda3\\lib\\site-packages\\IPython\\core\\interactiveshell.py\", line 2079, in showtraceback\n",
      "    stb = self.InteractiveTB.structured_traceback(etype,\n",
      "  File \"c:\\Users\\user\\anaconda3\\lib\\site-packages\\IPython\\core\\ultratb.py\", line 1367, in structured_traceback\n",
      "    return FormattedTB.structured_traceback(\n",
      "  File \"c:\\Users\\user\\anaconda3\\lib\\site-packages\\IPython\\core\\ultratb.py\", line 1267, in structured_traceback\n",
      "    return VerboseTB.structured_traceback(\n",
      "  File \"c:\\Users\\user\\anaconda3\\lib\\site-packages\\IPython\\core\\ultratb.py\", line 1134, in structured_traceback\n",
      "    exception = self.get_parts_of_chained_exception(evalue)\n",
      "  File \"c:\\Users\\user\\anaconda3\\lib\\site-packages\\IPython\\core\\ultratb.py\", line 473, in get_parts_of_chained_exception\n",
      "    return chained_evalue.__class__, chained_evalue, chained_evalue.__traceback__\n",
      "AttributeError: 'str' object has no attribute '__traceback__'\n",
      "\n",
      "During handling of the above exception, another exception occurred:\n",
      "\n",
      "Traceback (most recent call last):\n",
      "  File \"c:\\Users\\user\\anaconda3\\lib\\site-packages\\IPython\\core\\interactiveshell.py\", line 2077, in showtraceback\n",
      "    stb = value._render_traceback_()\n",
      "AttributeError: 'AttributeError' object has no attribute '_render_traceback_'\n",
      "\n",
      "During handling of the above exception, another exception occurred:\n",
      "\n",
      "Traceback (most recent call last):\n",
      "  File \"c:\\Users\\user\\anaconda3\\lib\\site-packages\\IPython\\core\\interactiveshell.py\", line 2960, in _run_cell\n",
      "    return runner(coro)\n",
      "  File \"c:\\Users\\user\\anaconda3\\lib\\site-packages\\IPython\\core\\async_helpers.py\", line 78, in _pseudo_sync_runner\n",
      "    coro.send(None)\n",
      "  File \"c:\\Users\\user\\anaconda3\\lib\\site-packages\\IPython\\core\\interactiveshell.py\", line 3185, in run_cell_async\n",
      "    has_raised = await self.run_ast_nodes(code_ast.body, cell_name,\n",
      "  File \"c:\\Users\\user\\anaconda3\\lib\\site-packages\\IPython\\core\\interactiveshell.py\", line 3396, in run_ast_nodes\n",
      "    self.showtraceback()\n",
      "  File \"c:\\Users\\user\\anaconda3\\lib\\site-packages\\IPython\\core\\interactiveshell.py\", line 2079, in showtraceback\n",
      "    stb = self.InteractiveTB.structured_traceback(etype,\n",
      "  File \"c:\\Users\\user\\anaconda3\\lib\\site-packages\\IPython\\core\\ultratb.py\", line 1367, in structured_traceback\n",
      "    return FormattedTB.structured_traceback(\n",
      "  File \"c:\\Users\\user\\anaconda3\\lib\\site-packages\\IPython\\core\\ultratb.py\", line 1267, in structured_traceback\n",
      "    return VerboseTB.structured_traceback(\n",
      "  File \"c:\\Users\\user\\anaconda3\\lib\\site-packages\\IPython\\core\\ultratb.py\", line 1144, in structured_traceback\n",
      "    exception = self.get_parts_of_chained_exception(evalue)\n",
      "  File \"c:\\Users\\user\\anaconda3\\lib\\site-packages\\IPython\\core\\ultratb.py\", line 473, in get_parts_of_chained_exception\n",
      "    return chained_evalue.__class__, chained_evalue, chained_evalue.__traceback__\n",
      "AttributeError: 'str' object has no attribute '__traceback__'\n",
      "\n",
      "During handling of the above exception, another exception occurred:\n",
      "\n",
      "Traceback (most recent call last):\n",
      "  File \"c:\\Users\\user\\anaconda3\\lib\\site-packages\\IPython\\core\\interactiveshell.py\", line 2077, in showtraceback\n",
      "    stb = value._render_traceback_()\n",
      "AttributeError: 'AttributeError' object has no attribute '_render_traceback_'\n",
      "\n",
      "During handling of the above exception, another exception occurred:\n",
      "\n",
      "Traceback (most recent call last):\n",
      "  File \"c:\\Users\\user\\anaconda3\\lib\\site-packages\\ipykernel\\kernelbase.py\", line 406, in dispatch_shell\n",
      "    await result\n",
      "  File \"c:\\Users\\user\\anaconda3\\lib\\site-packages\\ipykernel\\kernelbase.py\", line 730, in execute_request\n",
      "    reply_content = await reply_content\n",
      "  File \"c:\\Users\\user\\anaconda3\\lib\\site-packages\\ipykernel\\ipkernel.py\", line 390, in do_execute\n",
      "    res = shell.run_cell(code, store_history=store_history, silent=silent)\n",
      "  File \"c:\\Users\\user\\anaconda3\\lib\\site-packages\\ipykernel\\zmqshell.py\", line 528, in run_cell\n",
      "    return super().run_cell(*args, **kwargs)\n",
      "  File \"c:\\Users\\user\\anaconda3\\lib\\site-packages\\IPython\\core\\interactiveshell.py\", line 2914, in run_cell\n",
      "    result = self._run_cell(\n",
      "  File \"c:\\Users\\user\\anaconda3\\lib\\site-packages\\IPython\\core\\interactiveshell.py\", line 2965, in _run_cell\n",
      "    self.showtraceback(running_compiled_code=True)\n",
      "  File \"c:\\Users\\user\\anaconda3\\lib\\site-packages\\IPython\\core\\interactiveshell.py\", line 2079, in showtraceback\n",
      "    stb = self.InteractiveTB.structured_traceback(etype,\n",
      "  File \"c:\\Users\\user\\anaconda3\\lib\\site-packages\\IPython\\core\\ultratb.py\", line 1367, in structured_traceback\n",
      "    return FormattedTB.structured_traceback(\n",
      "  File \"c:\\Users\\user\\anaconda3\\lib\\site-packages\\IPython\\core\\ultratb.py\", line 1267, in structured_traceback\n",
      "    return VerboseTB.structured_traceback(\n",
      "  File \"c:\\Users\\user\\anaconda3\\lib\\site-packages\\IPython\\core\\ultratb.py\", line 1144, in structured_traceback\n",
      "    exception = self.get_parts_of_chained_exception(evalue)\n",
      "  File \"c:\\Users\\user\\anaconda3\\lib\\site-packages\\IPython\\core\\ultratb.py\", line 473, in get_parts_of_chained_exception\n",
      "    return chained_evalue.__class__, chained_evalue, chained_evalue.__traceback__\n",
      "AttributeError: 'str' object has no attribute '__traceback__'\n",
      "\n",
      "During handling of the above exception, another exception occurred:\n",
      "\n",
      "Traceback (most recent call last):\n",
      "  File \"c:\\Users\\user\\anaconda3\\lib\\logging\\__init__.py\", line 1083, in emit\n",
      "    msg = self.format(record)\n",
      "  File \"c:\\Users\\user\\anaconda3\\lib\\logging\\__init__.py\", line 927, in format\n",
      "    return fmt.format(record)\n",
      "  File \"c:\\Users\\user\\anaconda3\\lib\\site-packages\\traitlets\\config\\application.py\", line 117, in format\n",
      "    return super(LevelFormatter, self).format(record)\n",
      "  File \"c:\\Users\\user\\anaconda3\\lib\\logging\\__init__.py\", line 671, in format\n",
      "    record.exc_text = self.formatException(record.exc_info)\n",
      "  File \"c:\\Users\\user\\anaconda3\\lib\\logging\\__init__.py\", line 621, in formatException\n",
      "    traceback.print_exception(ei[0], ei[1], tb, None, sio)\n",
      "  File \"c:\\Users\\user\\anaconda3\\lib\\traceback.py\", line 103, in print_exception\n",
      "    for line in TracebackException(\n",
      "  File \"c:\\Users\\user\\anaconda3\\lib\\traceback.py\", line 495, in __init__\n",
      "    context = TracebackException(\n",
      "  File \"c:\\Users\\user\\anaconda3\\lib\\traceback.py\", line 495, in __init__\n",
      "    context = TracebackException(\n",
      "  File \"c:\\Users\\user\\anaconda3\\lib\\traceback.py\", line 495, in __init__\n",
      "    context = TracebackException(\n",
      "  [Previous line repeated 3 more times]\n",
      "  File \"c:\\Users\\user\\anaconda3\\lib\\traceback.py\", line 486, in __init__\n",
      "    exc_value.__cause__.__traceback__,\n",
      "AttributeError: 'str' object has no attribute '__traceback__'\n",
      "\n",
      "During handling of the above exception, another exception occurred:\n",
      "\n",
      "Traceback (most recent call last):\n",
      "  File \"c:\\Users\\user\\anaconda3\\lib\\site-packages\\ipykernel\\kernelbase.py\", line 510, in dispatch_queue\n",
      "    await self.process_one()\n",
      "  File \"c:\\Users\\user\\anaconda3\\lib\\site-packages\\ipykernel\\kernelbase.py\", line 499, in process_one\n",
      "    await dispatch(*args)\n",
      "  File \"c:\\Users\\user\\anaconda3\\lib\\site-packages\\ipykernel\\kernelbase.py\", line 408, in dispatch_shell\n",
      "    self.log.error(\"Exception in message handler:\", exc_info=True)\n",
      "  File \"c:\\Users\\user\\anaconda3\\lib\\logging\\__init__.py\", line 1475, in error\n",
      "    self._log(ERROR, msg, args, **kwargs)\n",
      "  File \"c:\\Users\\user\\anaconda3\\lib\\logging\\__init__.py\", line 1589, in _log\n",
      "    self.handle(record)\n",
      "  File \"c:\\Users\\user\\anaconda3\\lib\\logging\\__init__.py\", line 1599, in handle\n",
      "    self.callHandlers(record)\n",
      "  File \"c:\\Users\\user\\anaconda3\\lib\\logging\\__init__.py\", line 1661, in callHandlers\n",
      "    hdlr.handle(record)\n",
      "  File \"c:\\Users\\user\\anaconda3\\lib\\logging\\__init__.py\", line 952, in handle\n",
      "    self.emit(record)\n",
      "  File \"c:\\Users\\user\\anaconda3\\lib\\logging\\__init__.py\", line 1091, in emit\n",
      "    self.handleError(record)\n",
      "  File \"c:\\Users\\user\\anaconda3\\lib\\logging\\__init__.py\", line 1005, in handleError\n",
      "    traceback.print_exception(t, v, tb, None, sys.stderr)\n",
      "  File \"c:\\Users\\user\\anaconda3\\lib\\traceback.py\", line 103, in print_exception\n",
      "    for line in TracebackException(\n",
      "  File \"c:\\Users\\user\\anaconda3\\lib\\traceback.py\", line 495, in __init__\n",
      "    context = TracebackException(\n",
      "  File \"c:\\Users\\user\\anaconda3\\lib\\traceback.py\", line 495, in __init__\n",
      "    context = TracebackException(\n",
      "  File \"c:\\Users\\user\\anaconda3\\lib\\traceback.py\", line 495, in __init__\n",
      "    context = TracebackException(\n",
      "  [Previous line repeated 4 more times]\n",
      "  File \"c:\\Users\\user\\anaconda3\\lib\\traceback.py\", line 486, in __init__\n",
      "    exc_value.__cause__.__traceback__,\n",
      "AttributeError: 'str' object has no attribute '__traceback__'\n",
      "\n",
      "During handling of the above exception, another exception occurred:\n",
      "\n",
      "Traceback (most recent call last):\n",
      "  File \"c:\\Users\\user\\anaconda3\\lib\\logging\\__init__.py\", line 1083, in emit\n",
      "    msg = self.format(record)\n",
      "  File \"c:\\Users\\user\\anaconda3\\lib\\logging\\__init__.py\", line 927, in format\n",
      "    return fmt.format(record)\n",
      "  File \"c:\\Users\\user\\anaconda3\\lib\\site-packages\\traitlets\\config\\application.py\", line 117, in format\n",
      "    return super(LevelFormatter, self).format(record)\n",
      "  File \"c:\\Users\\user\\anaconda3\\lib\\logging\\__init__.py\", line 671, in format\n",
      "    record.exc_text = self.formatException(record.exc_info)\n",
      "  File \"c:\\Users\\user\\anaconda3\\lib\\logging\\__init__.py\", line 621, in formatException\n",
      "    traceback.print_exception(ei[0], ei[1], tb, None, sio)\n",
      "  File \"c:\\Users\\user\\anaconda3\\lib\\traceback.py\", line 103, in print_exception\n",
      "    for line in TracebackException(\n",
      "  File \"c:\\Users\\user\\anaconda3\\lib\\traceback.py\", line 495, in __init__\n",
      "    context = TracebackException(\n",
      "  File \"c:\\Users\\user\\anaconda3\\lib\\traceback.py\", line 495, in __init__\n",
      "    context = TracebackException(\n",
      "  File \"c:\\Users\\user\\anaconda3\\lib\\traceback.py\", line 495, in __init__\n",
      "    context = TracebackException(\n",
      "  [Previous line repeated 5 more times]\n",
      "  File \"c:\\Users\\user\\anaconda3\\lib\\traceback.py\", line 486, in __init__\n",
      "    exc_value.__cause__.__traceback__,\n",
      "AttributeError: 'str' object has no attribute '__traceback__'\n",
      "\n",
      "During handling of the above exception, another exception occurred:\n",
      "\n",
      "Traceback (most recent call last):\n",
      "  File \"c:\\Users\\user\\anaconda3\\lib\\site-packages\\tornado\\ioloop.py\", line 741, in _run_callback\n",
      "    ret = callback()\n",
      "  File \"c:\\Users\\user\\anaconda3\\lib\\site-packages\\tornado\\ioloop.py\", line 765, in _discard_future_result\n",
      "    future.result()\n",
      "  File \"c:\\Users\\user\\anaconda3\\lib\\site-packages\\ipykernel\\kernelbase.py\", line 512, in dispatch_queue\n",
      "    self.log.exception(\"Error in message handler\")\n",
      "  File \"c:\\Users\\user\\anaconda3\\lib\\logging\\__init__.py\", line 1481, in exception\n",
      "    self.error(msg, *args, exc_info=exc_info, **kwargs)\n",
      "  File \"c:\\Users\\user\\anaconda3\\lib\\logging\\__init__.py\", line 1475, in error\n",
      "    self._log(ERROR, msg, args, **kwargs)\n",
      "  File \"c:\\Users\\user\\anaconda3\\lib\\logging\\__init__.py\", line 1589, in _log\n",
      "    self.handle(record)\n",
      "  File \"c:\\Users\\user\\anaconda3\\lib\\logging\\__init__.py\", line 1599, in handle\n",
      "    self.callHandlers(record)\n",
      "  File \"c:\\Users\\user\\anaconda3\\lib\\logging\\__init__.py\", line 1661, in callHandlers\n",
      "    hdlr.handle(record)\n",
      "  File \"c:\\Users\\user\\anaconda3\\lib\\logging\\__init__.py\", line 952, in handle\n",
      "    self.emit(record)\n",
      "  File \"c:\\Users\\user\\anaconda3\\lib\\logging\\__init__.py\", line 1091, in emit\n",
      "    self.handleError(record)\n",
      "  File \"c:\\Users\\user\\anaconda3\\lib\\logging\\__init__.py\", line 1005, in handleError\n",
      "    traceback.print_exception(t, v, tb, None, sys.stderr)\n",
      "  File \"c:\\Users\\user\\anaconda3\\lib\\traceback.py\", line 103, in print_exception\n",
      "    for line in TracebackException(\n",
      "  File \"c:\\Users\\user\\anaconda3\\lib\\traceback.py\", line 495, in __init__\n",
      "    context = TracebackException(\n",
      "  File \"c:\\Users\\user\\anaconda3\\lib\\traceback.py\", line 495, in __init__\n",
      "    context = TracebackException(\n",
      "  File \"c:\\Users\\user\\anaconda3\\lib\\traceback.py\", line 495, in __init__\n",
      "    context = TracebackException(\n",
      "  [Previous line repeated 6 more times]\n",
      "  File \"c:\\Users\\user\\anaconda3\\lib\\traceback.py\", line 486, in __init__\n",
      "    exc_value.__cause__.__traceback__,\n",
      "AttributeError: 'str' object has no attribute '__traceback__'\n",
      "\n",
      "During handling of the above exception, another exception occurred:\n",
      "\n",
      "Traceback (most recent call last):\n",
      "  File \"c:\\Users\\user\\anaconda3\\lib\\logging\\__init__.py\", line 1083, in emit\n",
      "    msg = self.format(record)\n",
      "  File \"c:\\Users\\user\\anaconda3\\lib\\logging\\__init__.py\", line 927, in format\n",
      "    return fmt.format(record)\n",
      "  File \"c:\\Users\\user\\anaconda3\\lib\\logging\\__init__.py\", line 671, in format\n",
      "    record.exc_text = self.formatException(record.exc_info)\n",
      "  File \"c:\\Users\\user\\anaconda3\\lib\\logging\\__init__.py\", line 621, in formatException\n",
      "    traceback.print_exception(ei[0], ei[1], tb, None, sio)\n",
      "  File \"c:\\Users\\user\\anaconda3\\lib\\traceback.py\", line 103, in print_exception\n",
      "    for line in TracebackException(\n",
      "  File \"c:\\Users\\user\\anaconda3\\lib\\traceback.py\", line 495, in __init__\n",
      "    context = TracebackException(\n",
      "  File \"c:\\Users\\user\\anaconda3\\lib\\traceback.py\", line 495, in __init__\n",
      "    context = TracebackException(\n",
      "  File \"c:\\Users\\user\\anaconda3\\lib\\traceback.py\", line 495, in __init__\n",
      "    context = TracebackException(\n",
      "  [Previous line repeated 7 more times]\n",
      "  File \"c:\\Users\\user\\anaconda3\\lib\\traceback.py\", line 486, in __init__\n",
      "    exc_value.__cause__.__traceback__,\n",
      "AttributeError: 'str' object has no attribute '__traceback__'\n",
      "\n",
      "During handling of the above exception, another exception occurred:\n",
      "\n",
      "Traceback (most recent call last):\n",
      "  File \"c:\\Users\\user\\anaconda3\\lib\\asyncio\\events.py\", line 80, in _run\n",
      "    self._context.run(self._callback, *self._args)\n",
      "  File \"c:\\Users\\user\\anaconda3\\lib\\site-packages\\tornado\\ioloop.py\", line 688, in <lambda>\n",
      "    lambda f: self._run_callback(functools.partial(callback, future))\n",
      "  File \"c:\\Users\\user\\anaconda3\\lib\\site-packages\\tornado\\ioloop.py\", line 761, in _run_callback\n",
      "    app_log.error(\"Exception in callback %r\", callback, exc_info=True)\n",
      "  File \"c:\\Users\\user\\anaconda3\\lib\\logging\\__init__.py\", line 1475, in error\n",
      "    self._log(ERROR, msg, args, **kwargs)\n",
      "  File \"c:\\Users\\user\\anaconda3\\lib\\logging\\__init__.py\", line 1589, in _log\n",
      "    self.handle(record)\n",
      "  File \"c:\\Users\\user\\anaconda3\\lib\\logging\\__init__.py\", line 1599, in handle\n",
      "    self.callHandlers(record)\n",
      "  File \"c:\\Users\\user\\anaconda3\\lib\\logging\\__init__.py\", line 1661, in callHandlers\n",
      "    hdlr.handle(record)\n",
      "  File \"c:\\Users\\user\\anaconda3\\lib\\logging\\__init__.py\", line 952, in handle\n",
      "    self.emit(record)\n",
      "  File \"c:\\Users\\user\\anaconda3\\lib\\logging\\__init__.py\", line 1091, in emit\n",
      "    self.handleError(record)\n",
      "  File \"c:\\Users\\user\\anaconda3\\lib\\logging\\__init__.py\", line 1005, in handleError\n",
      "    traceback.print_exception(t, v, tb, None, sys.stderr)\n",
      "  File \"c:\\Users\\user\\anaconda3\\lib\\traceback.py\", line 103, in print_exception\n",
      "    for line in TracebackException(\n",
      "  File \"c:\\Users\\user\\anaconda3\\lib\\traceback.py\", line 495, in __init__\n",
      "    context = TracebackException(\n",
      "  File \"c:\\Users\\user\\anaconda3\\lib\\traceback.py\", line 495, in __init__\n",
      "    context = TracebackException(\n",
      "  File \"c:\\Users\\user\\anaconda3\\lib\\traceback.py\", line 495, in __init__\n",
      "    context = TracebackException(\n",
      "  [Previous line repeated 8 more times]\n",
      "  File \"c:\\Users\\user\\anaconda3\\lib\\traceback.py\", line 486, in __init__\n",
      "    exc_value.__cause__.__traceback__,\n",
      "AttributeError: 'str' object has no attribute '__traceback__'\n",
      "\n",
      "During handling of the above exception, another exception occurred:\n",
      "\n",
      "Traceback (most recent call last):\n",
      "  File \"c:\\Users\\user\\anaconda3\\lib\\logging\\__init__.py\", line 1083, in emit\n",
      "    msg = self.format(record)\n",
      "  File \"c:\\Users\\user\\anaconda3\\lib\\logging\\__init__.py\", line 927, in format\n",
      "    return fmt.format(record)\n",
      "  File \"c:\\Users\\user\\anaconda3\\lib\\logging\\__init__.py\", line 671, in format\n",
      "    record.exc_text = self.formatException(record.exc_info)\n",
      "  File \"c:\\Users\\user\\anaconda3\\lib\\logging\\__init__.py\", line 621, in formatException\n",
      "    traceback.print_exception(ei[0], ei[1], tb, None, sio)\n",
      "  File \"c:\\Users\\user\\anaconda3\\lib\\traceback.py\", line 103, in print_exception\n",
      "    for line in TracebackException(\n",
      "  File \"c:\\Users\\user\\anaconda3\\lib\\traceback.py\", line 495, in __init__\n",
      "    context = TracebackException(\n",
      "  File \"c:\\Users\\user\\anaconda3\\lib\\traceback.py\", line 495, in __init__\n",
      "    context = TracebackException(\n",
      "  File \"c:\\Users\\user\\anaconda3\\lib\\traceback.py\", line 495, in __init__\n",
      "    context = TracebackException(\n",
      "  [Previous line repeated 9 more times]\n",
      "  File \"c:\\Users\\user\\anaconda3\\lib\\traceback.py\", line 486, in __init__\n",
      "    exc_value.__cause__.__traceback__,\n",
      "AttributeError: 'str' object has no attribute '__traceback__'\n",
      "\n",
      "During handling of the above exception, another exception occurred:\n",
      "\n",
      "Traceback (most recent call last):\n",
      "  File \"c:\\Users\\user\\anaconda3\\lib\\asyncio\\base_events.py\", line 1779, in call_exception_handler\n",
      "    self.default_exception_handler(context)\n",
      "  File \"c:\\Users\\user\\anaconda3\\lib\\asyncio\\base_events.py\", line 1753, in default_exception_handler\n",
      "    logger.error('\\n'.join(log_lines), exc_info=exc_info)\n",
      "  File \"c:\\Users\\user\\anaconda3\\lib\\logging\\__init__.py\", line 1475, in error\n",
      "    self._log(ERROR, msg, args, **kwargs)\n",
      "  File \"c:\\Users\\user\\anaconda3\\lib\\logging\\__init__.py\", line 1589, in _log\n",
      "    self.handle(record)\n",
      "  File \"c:\\Users\\user\\anaconda3\\lib\\logging\\__init__.py\", line 1599, in handle\n",
      "    self.callHandlers(record)\n",
      "  File \"c:\\Users\\user\\anaconda3\\lib\\logging\\__init__.py\", line 1669, in callHandlers\n",
      "    lastResort.handle(record)\n",
      "  File \"c:\\Users\\user\\anaconda3\\lib\\logging\\__init__.py\", line 952, in handle\n",
      "    self.emit(record)\n",
      "  File \"c:\\Users\\user\\anaconda3\\lib\\logging\\__init__.py\", line 1091, in emit\n",
      "    self.handleError(record)\n",
      "  File \"c:\\Users\\user\\anaconda3\\lib\\logging\\__init__.py\", line 1005, in handleError\n",
      "    traceback.print_exception(t, v, tb, None, sys.stderr)\n",
      "  File \"c:\\Users\\user\\anaconda3\\lib\\traceback.py\", line 103, in print_exception\n",
      "    for line in TracebackException(\n",
      "  File \"c:\\Users\\user\\anaconda3\\lib\\traceback.py\", line 495, in __init__\n",
      "    context = TracebackException(\n",
      "  File \"c:\\Users\\user\\anaconda3\\lib\\traceback.py\", line 495, in __init__\n",
      "    context = TracebackException(\n",
      "  File \"c:\\Users\\user\\anaconda3\\lib\\traceback.py\", line 495, in __init__\n",
      "    context = TracebackException(\n",
      "  [Previous line repeated 10 more times]\n",
      "  File \"c:\\Users\\user\\anaconda3\\lib\\traceback.py\", line 486, in __init__\n",
      "    exc_value.__cause__.__traceback__,\n",
      "AttributeError: 'str' object has no attribute '__traceback__'\n",
      "\n",
      "During handling of the above exception, another exception occurred:\n",
      "\n",
      "Traceback (most recent call last):\n",
      "  File \"c:\\Users\\user\\anaconda3\\lib\\logging\\__init__.py\", line 1083, in emit\n",
      "    msg = self.format(record)\n",
      "  File \"c:\\Users\\user\\anaconda3\\lib\\logging\\__init__.py\", line 927, in format\n",
      "    return fmt.format(record)\n",
      "  File \"c:\\Users\\user\\anaconda3\\lib\\logging\\__init__.py\", line 671, in format\n",
      "    record.exc_text = self.formatException(record.exc_info)\n",
      "  File \"c:\\Users\\user\\anaconda3\\lib\\logging\\__init__.py\", line 621, in formatException\n",
      "    traceback.print_exception(ei[0], ei[1], tb, None, sio)\n",
      "  File \"c:\\Users\\user\\anaconda3\\lib\\traceback.py\", line 103, in print_exception\n",
      "    for line in TracebackException(\n",
      "  File \"c:\\Users\\user\\anaconda3\\lib\\traceback.py\", line 495, in __init__\n",
      "    context = TracebackException(\n",
      "  File \"c:\\Users\\user\\anaconda3\\lib\\traceback.py\", line 495, in __init__\n",
      "    context = TracebackException(\n",
      "  File \"c:\\Users\\user\\anaconda3\\lib\\traceback.py\", line 495, in __init__\n",
      "    context = TracebackException(\n",
      "  [Previous line repeated 11 more times]\n",
      "  File \"c:\\Users\\user\\anaconda3\\lib\\traceback.py\", line 486, in __init__\n",
      "    exc_value.__cause__.__traceback__,\n",
      "AttributeError: 'str' object has no attribute '__traceback__'\n",
      "\n",
      "During handling of the above exception, another exception occurred:\n",
      "\n",
      "Traceback (most recent call last):\n",
      "  File \"c:\\Users\\user\\anaconda3\\lib\\runpy.py\", line 197, in _run_module_as_main\n",
      "    return _run_code(code, main_globals, None,\n",
      "  File \"c:\\Users\\user\\anaconda3\\lib\\runpy.py\", line 87, in _run_code\n",
      "    exec(code, run_globals)\n",
      "  File \"c:\\Users\\user\\anaconda3\\lib\\site-packages\\ipykernel_launcher.py\", line 17, in <module>\n",
      "    app.launch_new_instance()\n",
      "  File \"c:\\Users\\user\\anaconda3\\lib\\site-packages\\traitlets\\config\\application.py\", line 846, in launch_instance\n",
      "    app.start()\n",
      "  File \"c:\\Users\\user\\anaconda3\\lib\\site-packages\\ipykernel\\kernelapp.py\", line 712, in start\n",
      "    self.io_loop.start()\n",
      "  File \"c:\\Users\\user\\anaconda3\\lib\\site-packages\\tornado\\platform\\asyncio.py\", line 199, in start\n",
      "    self.asyncio_loop.run_forever()\n",
      "  File \"c:\\Users\\user\\anaconda3\\lib\\asyncio\\base_events.py\", line 601, in run_forever\n",
      "    self._run_once()\n",
      "  File \"c:\\Users\\user\\anaconda3\\lib\\asyncio\\base_events.py\", line 1905, in _run_once\n",
      "    handle._run()\n",
      "  File \"c:\\Users\\user\\anaconda3\\lib\\asyncio\\events.py\", line 94, in _run\n",
      "    self._loop.call_exception_handler(context)\n",
      "  File \"c:\\Users\\user\\anaconda3\\lib\\asyncio\\base_events.py\", line 1786, in call_exception_handler\n",
      "    logger.error('Exception in default exception handler',\n",
      "  File \"c:\\Users\\user\\anaconda3\\lib\\logging\\__init__.py\", line 1475, in error\n",
      "    self._log(ERROR, msg, args, **kwargs)\n",
      "  File \"c:\\Users\\user\\anaconda3\\lib\\logging\\__init__.py\", line 1589, in _log\n",
      "    self.handle(record)\n",
      "  File \"c:\\Users\\user\\anaconda3\\lib\\logging\\__init__.py\", line 1599, in handle\n",
      "    self.callHandlers(record)\n",
      "  File \"c:\\Users\\user\\anaconda3\\lib\\logging\\__init__.py\", line 1669, in callHandlers\n",
      "    lastResort.handle(record)\n",
      "  File \"c:\\Users\\user\\anaconda3\\lib\\logging\\__init__.py\", line 952, in handle\n",
      "    self.emit(record)\n",
      "  File \"c:\\Users\\user\\anaconda3\\lib\\logging\\__init__.py\", line 1091, in emit\n",
      "    self.handleError(record)\n",
      "  File \"c:\\Users\\user\\anaconda3\\lib\\logging\\__init__.py\", line 1005, in handleError\n",
      "    traceback.print_exception(t, v, tb, None, sys.stderr)\n",
      "  File \"c:\\Users\\user\\anaconda3\\lib\\traceback.py\", line 103, in print_exception\n",
      "    for line in TracebackException(\n",
      "  File \"c:\\Users\\user\\anaconda3\\lib\\traceback.py\", line 495, in __init__\n",
      "    context = TracebackException(\n",
      "  File \"c:\\Users\\user\\anaconda3\\lib\\traceback.py\", line 495, in __init__\n",
      "    context = TracebackException(\n",
      "  File \"c:\\Users\\user\\anaconda3\\lib\\traceback.py\", line 495, in __init__\n",
      "    context = TracebackException(\n",
      "  [Previous line repeated 12 more times]\n",
      "  File \"c:\\Users\\user\\anaconda3\\lib\\traceback.py\", line 486, in __init__\n",
      "    exc_value.__cause__.__traceback__,\n",
      "AttributeError: 'str' object has no attribute '__traceback__'\n"
     ]
    },
    {
     "ename": "",
     "evalue": "",
     "output_type": "error",
     "traceback": [
      "\u001b[1;31mCanceled future for execute_request message before replies were done"
     ]
    },
    {
     "ename": "",
     "evalue": "",
     "output_type": "error",
     "traceback": [
      "\u001b[1;31m현재 셀 또는 이전 셀에서 코드를 실행하는 동안 Kernel이 충돌했습니다. 셀의 코드를 검토하여 오류의 가능한 원인을 식별하세요. 자세한 내용을 보려면 <a href='https://aka.ms/vscodeJupyterKernelCrash'> 여기 </a> 를 클릭하세요. 자세한 내용은 Jupyter <a href='command:jupyter.viewOutput'>로그</a>를 참조하세요."
     ]
    }
   ],
   "source": [
    "preprocessing(\"맛있는김치찌개\")"
   ]
  },
  {
   "cell_type": "code",
   "execution_count": 27,
   "metadata": {},
   "outputs": [],
   "source": [
    "for_apply = lambda x : preprocessing(x)[\"menu\"]"
   ]
  },
  {
   "cell_type": "code",
   "execution_count": 28,
   "metadata": {},
   "outputs": [
    {
     "name": "stderr",
     "output_type": "stream",
     "text": [
      "--- Logging error ---\n",
      "--- Logging error ---\n",
      "--- Logging error ---\n",
      "--- Logging error ---\n",
      "--- Logging error ---\n",
      "Error in sys.excepthook:\n",
      "Traceback (most recent call last):\n",
      "  File \"c:\\Users\\user\\anaconda3\\lib\\traceback.py\", line 495, in __init__\n",
      "    context = TracebackException(\n",
      "  File \"c:\\Users\\user\\anaconda3\\lib\\traceback.py\", line 495, in __init__\n",
      "    context = TracebackException(\n",
      "  File \"c:\\Users\\user\\anaconda3\\lib\\traceback.py\", line 495, in __init__\n",
      "    context = TracebackException(\n",
      "  [Previous line repeated 13 more times]\n",
      "  File \"c:\\Users\\user\\anaconda3\\lib\\traceback.py\", line 486, in __init__\n",
      "    exc_value.__cause__.__traceback__,\n",
      "AttributeError: 'str' object has no attribute '__traceback__'\n",
      "\n",
      "Original exception was:\n",
      "TypeError: print_exception(): Exception expected for value, str found\n",
      "\n",
      "The above exception was the direct cause of the following exception:\n",
      "\n",
      "Traceback (most recent call last):\n",
      "  File \"c:\\Users\\user\\anaconda3\\lib\\site-packages\\IPython\\core\\interactiveshell.py\", line 3457, in run_code\n",
      "    exec(code_obj, self.user_global_ns, self.user_ns)\n",
      "  File \"C:\\Users\\user\\AppData\\Local\\Temp\\ipykernel_9188\\642592961.py\", line 1, in <module>\n",
      "  File \"C:\\Users\\user\\AppData\\Local\\Temp\\ipykernel_9188\\2581301726.py\", line 1, in <lambda>\n",
      "  File \"C:\\Users\\user\\AppData\\Local\\Temp\\ipykernel_9188\\3617179043.py\", line 9, in preprocessing\n",
      "  File \"C:\\Users\\user\\AppData\\Local\\Temp\\ipykernel_9188\\3622754509.py\", line 81, in <lambda>\n",
      "  File \"C:\\Users\\user\\AppData\\Local\\Temp\\ipykernel_9188\\3622754509.py\", line 72, in is_option\n",
      "  File \"c:\\Users\\user\\anaconda3\\lib\\site-packages\\kiwipiepy\\_wrap.py\", line 1303, in space\n",
      "    return map(_space, super().analyze(text, 1, Match.ALL, echo=True))\n",
      "ValueError: `analyze` requires a `str` or an iterable of `str` parameters.\n",
      "\n",
      "During handling of the above exception, another exception occurred:\n",
      "\n",
      "Traceback (most recent call last):\n",
      "  File \"c:\\Users\\user\\anaconda3\\lib\\site-packages\\IPython\\core\\interactiveshell.py\", line 2077, in showtraceback\n",
      "    stb = value._render_traceback_()\n",
      "AttributeError: 'ValueError' object has no attribute '_render_traceback_'\n",
      "\n",
      "During handling of the above exception, another exception occurred:\n",
      "\n",
      "Traceback (most recent call last):\n",
      "  File \"c:\\Users\\user\\anaconda3\\lib\\site-packages\\IPython\\core\\interactiveshell.py\", line 3377, in run_ast_nodes\n",
      "    if (await self.run_code(code, result,  async_=asy)):\n",
      "  File \"c:\\Users\\user\\anaconda3\\lib\\site-packages\\IPython\\core\\interactiveshell.py\", line 3474, in run_code\n",
      "    self.showtraceback(running_compiled_code=True)\n",
      "  File \"c:\\Users\\user\\anaconda3\\lib\\site-packages\\IPython\\core\\interactiveshell.py\", line 2079, in showtraceback\n",
      "    stb = self.InteractiveTB.structured_traceback(etype,\n",
      "  File \"c:\\Users\\user\\anaconda3\\lib\\site-packages\\IPython\\core\\ultratb.py\", line 1367, in structured_traceback\n",
      "    return FormattedTB.structured_traceback(\n",
      "  File \"c:\\Users\\user\\anaconda3\\lib\\site-packages\\IPython\\core\\ultratb.py\", line 1267, in structured_traceback\n",
      "    return VerboseTB.structured_traceback(\n",
      "  File \"c:\\Users\\user\\anaconda3\\lib\\site-packages\\IPython\\core\\ultratb.py\", line 1134, in structured_traceback\n",
      "    exception = self.get_parts_of_chained_exception(evalue)\n",
      "  File \"c:\\Users\\user\\anaconda3\\lib\\site-packages\\IPython\\core\\ultratb.py\", line 473, in get_parts_of_chained_exception\n",
      "    return chained_evalue.__class__, chained_evalue, chained_evalue.__traceback__\n",
      "AttributeError: 'str' object has no attribute '__traceback__'\n",
      "\n",
      "During handling of the above exception, another exception occurred:\n",
      "\n",
      "Traceback (most recent call last):\n",
      "  File \"c:\\Users\\user\\anaconda3\\lib\\site-packages\\IPython\\core\\interactiveshell.py\", line 2077, in showtraceback\n",
      "    stb = value._render_traceback_()\n",
      "AttributeError: 'AttributeError' object has no attribute '_render_traceback_'\n",
      "\n",
      "During handling of the above exception, another exception occurred:\n",
      "\n",
      "Traceback (most recent call last):\n",
      "  File \"c:\\Users\\user\\anaconda3\\lib\\site-packages\\IPython\\core\\interactiveshell.py\", line 2960, in _run_cell\n",
      "    return runner(coro)\n",
      "  File \"c:\\Users\\user\\anaconda3\\lib\\site-packages\\IPython\\core\\async_helpers.py\", line 78, in _pseudo_sync_runner\n",
      "    coro.send(None)\n",
      "  File \"c:\\Users\\user\\anaconda3\\lib\\site-packages\\IPython\\core\\interactiveshell.py\", line 3185, in run_cell_async\n",
      "    has_raised = await self.run_ast_nodes(code_ast.body, cell_name,\n",
      "  File \"c:\\Users\\user\\anaconda3\\lib\\site-packages\\IPython\\core\\interactiveshell.py\", line 3396, in run_ast_nodes\n",
      "    self.showtraceback()\n",
      "  File \"c:\\Users\\user\\anaconda3\\lib\\site-packages\\IPython\\core\\interactiveshell.py\", line 2079, in showtraceback\n",
      "    stb = self.InteractiveTB.structured_traceback(etype,\n",
      "  File \"c:\\Users\\user\\anaconda3\\lib\\site-packages\\IPython\\core\\ultratb.py\", line 1367, in structured_traceback\n",
      "    return FormattedTB.structured_traceback(\n",
      "  File \"c:\\Users\\user\\anaconda3\\lib\\site-packages\\IPython\\core\\ultratb.py\", line 1267, in structured_traceback\n",
      "    return VerboseTB.structured_traceback(\n",
      "  File \"c:\\Users\\user\\anaconda3\\lib\\site-packages\\IPython\\core\\ultratb.py\", line 1144, in structured_traceback\n",
      "    exception = self.get_parts_of_chained_exception(evalue)\n",
      "  File \"c:\\Users\\user\\anaconda3\\lib\\site-packages\\IPython\\core\\ultratb.py\", line 473, in get_parts_of_chained_exception\n",
      "    return chained_evalue.__class__, chained_evalue, chained_evalue.__traceback__\n",
      "AttributeError: 'str' object has no attribute '__traceback__'\n",
      "\n",
      "During handling of the above exception, another exception occurred:\n",
      "\n",
      "Traceback (most recent call last):\n",
      "  File \"c:\\Users\\user\\anaconda3\\lib\\site-packages\\IPython\\core\\interactiveshell.py\", line 2077, in showtraceback\n",
      "    stb = value._render_traceback_()\n",
      "AttributeError: 'AttributeError' object has no attribute '_render_traceback_'\n",
      "\n",
      "During handling of the above exception, another exception occurred:\n",
      "\n",
      "Traceback (most recent call last):\n",
      "  File \"c:\\Users\\user\\anaconda3\\lib\\site-packages\\ipykernel\\kernelbase.py\", line 406, in dispatch_shell\n",
      "    await result\n",
      "  File \"c:\\Users\\user\\anaconda3\\lib\\site-packages\\ipykernel\\kernelbase.py\", line 730, in execute_request\n",
      "    reply_content = await reply_content\n",
      "  File \"c:\\Users\\user\\anaconda3\\lib\\site-packages\\ipykernel\\ipkernel.py\", line 390, in do_execute\n",
      "    res = shell.run_cell(code, store_history=store_history, silent=silent)\n",
      "  File \"c:\\Users\\user\\anaconda3\\lib\\site-packages\\ipykernel\\zmqshell.py\", line 528, in run_cell\n",
      "    return super().run_cell(*args, **kwargs)\n",
      "  File \"c:\\Users\\user\\anaconda3\\lib\\site-packages\\IPython\\core\\interactiveshell.py\", line 2914, in run_cell\n",
      "    result = self._run_cell(\n",
      "  File \"c:\\Users\\user\\anaconda3\\lib\\site-packages\\IPython\\core\\interactiveshell.py\", line 2965, in _run_cell\n",
      "    self.showtraceback(running_compiled_code=True)\n",
      "  File \"c:\\Users\\user\\anaconda3\\lib\\site-packages\\IPython\\core\\interactiveshell.py\", line 2079, in showtraceback\n",
      "    stb = self.InteractiveTB.structured_traceback(etype,\n",
      "  File \"c:\\Users\\user\\anaconda3\\lib\\site-packages\\IPython\\core\\ultratb.py\", line 1367, in structured_traceback\n",
      "    return FormattedTB.structured_traceback(\n",
      "  File \"c:\\Users\\user\\anaconda3\\lib\\site-packages\\IPython\\core\\ultratb.py\", line 1267, in structured_traceback\n",
      "    return VerboseTB.structured_traceback(\n",
      "  File \"c:\\Users\\user\\anaconda3\\lib\\site-packages\\IPython\\core\\ultratb.py\", line 1144, in structured_traceback\n",
      "    exception = self.get_parts_of_chained_exception(evalue)\n",
      "  File \"c:\\Users\\user\\anaconda3\\lib\\site-packages\\IPython\\core\\ultratb.py\", line 473, in get_parts_of_chained_exception\n",
      "    return chained_evalue.__class__, chained_evalue, chained_evalue.__traceback__\n",
      "AttributeError: 'str' object has no attribute '__traceback__'\n",
      "\n",
      "During handling of the above exception, another exception occurred:\n",
      "\n",
      "Traceback (most recent call last):\n",
      "  File \"c:\\Users\\user\\anaconda3\\lib\\logging\\__init__.py\", line 1083, in emit\n",
      "    msg = self.format(record)\n",
      "  File \"c:\\Users\\user\\anaconda3\\lib\\logging\\__init__.py\", line 927, in format\n",
      "    return fmt.format(record)\n",
      "  File \"c:\\Users\\user\\anaconda3\\lib\\site-packages\\traitlets\\config\\application.py\", line 117, in format\n",
      "    return super(LevelFormatter, self).format(record)\n",
      "  File \"c:\\Users\\user\\anaconda3\\lib\\logging\\__init__.py\", line 671, in format\n",
      "    record.exc_text = self.formatException(record.exc_info)\n",
      "  File \"c:\\Users\\user\\anaconda3\\lib\\logging\\__init__.py\", line 621, in formatException\n",
      "    traceback.print_exception(ei[0], ei[1], tb, None, sio)\n",
      "  File \"c:\\Users\\user\\anaconda3\\lib\\traceback.py\", line 103, in print_exception\n",
      "    for line in TracebackException(\n",
      "  File \"c:\\Users\\user\\anaconda3\\lib\\traceback.py\", line 495, in __init__\n",
      "    context = TracebackException(\n",
      "  File \"c:\\Users\\user\\anaconda3\\lib\\traceback.py\", line 495, in __init__\n",
      "    context = TracebackException(\n",
      "  File \"c:\\Users\\user\\anaconda3\\lib\\traceback.py\", line 495, in __init__\n",
      "    context = TracebackException(\n",
      "  [Previous line repeated 3 more times]\n",
      "  File \"c:\\Users\\user\\anaconda3\\lib\\traceback.py\", line 486, in __init__\n",
      "    exc_value.__cause__.__traceback__,\n",
      "AttributeError: 'str' object has no attribute '__traceback__'\n",
      "\n",
      "During handling of the above exception, another exception occurred:\n",
      "\n",
      "Traceback (most recent call last):\n",
      "  File \"c:\\Users\\user\\anaconda3\\lib\\site-packages\\ipykernel\\kernelbase.py\", line 510, in dispatch_queue\n",
      "    await self.process_one()\n",
      "  File \"c:\\Users\\user\\anaconda3\\lib\\site-packages\\ipykernel\\kernelbase.py\", line 499, in process_one\n",
      "    await dispatch(*args)\n",
      "  File \"c:\\Users\\user\\anaconda3\\lib\\site-packages\\ipykernel\\kernelbase.py\", line 408, in dispatch_shell\n",
      "    self.log.error(\"Exception in message handler:\", exc_info=True)\n",
      "  File \"c:\\Users\\user\\anaconda3\\lib\\logging\\__init__.py\", line 1475, in error\n",
      "    self._log(ERROR, msg, args, **kwargs)\n",
      "  File \"c:\\Users\\user\\anaconda3\\lib\\logging\\__init__.py\", line 1589, in _log\n",
      "    self.handle(record)\n",
      "  File \"c:\\Users\\user\\anaconda3\\lib\\logging\\__init__.py\", line 1599, in handle\n",
      "    self.callHandlers(record)\n",
      "  File \"c:\\Users\\user\\anaconda3\\lib\\logging\\__init__.py\", line 1661, in callHandlers\n",
      "    hdlr.handle(record)\n",
      "  File \"c:\\Users\\user\\anaconda3\\lib\\logging\\__init__.py\", line 952, in handle\n",
      "    self.emit(record)\n",
      "  File \"c:\\Users\\user\\anaconda3\\lib\\logging\\__init__.py\", line 1091, in emit\n",
      "    self.handleError(record)\n",
      "  File \"c:\\Users\\user\\anaconda3\\lib\\logging\\__init__.py\", line 1005, in handleError\n",
      "    traceback.print_exception(t, v, tb, None, sys.stderr)\n",
      "  File \"c:\\Users\\user\\anaconda3\\lib\\traceback.py\", line 103, in print_exception\n",
      "    for line in TracebackException(\n",
      "  File \"c:\\Users\\user\\anaconda3\\lib\\traceback.py\", line 495, in __init__\n",
      "    context = TracebackException(\n",
      "  File \"c:\\Users\\user\\anaconda3\\lib\\traceback.py\", line 495, in __init__\n",
      "    context = TracebackException(\n",
      "  File \"c:\\Users\\user\\anaconda3\\lib\\traceback.py\", line 495, in __init__\n",
      "    context = TracebackException(\n",
      "  [Previous line repeated 4 more times]\n",
      "  File \"c:\\Users\\user\\anaconda3\\lib\\traceback.py\", line 486, in __init__\n",
      "    exc_value.__cause__.__traceback__,\n",
      "AttributeError: 'str' object has no attribute '__traceback__'\n",
      "\n",
      "During handling of the above exception, another exception occurred:\n",
      "\n",
      "Traceback (most recent call last):\n",
      "  File \"c:\\Users\\user\\anaconda3\\lib\\logging\\__init__.py\", line 1083, in emit\n",
      "    msg = self.format(record)\n",
      "  File \"c:\\Users\\user\\anaconda3\\lib\\logging\\__init__.py\", line 927, in format\n",
      "    return fmt.format(record)\n",
      "  File \"c:\\Users\\user\\anaconda3\\lib\\site-packages\\traitlets\\config\\application.py\", line 117, in format\n",
      "    return super(LevelFormatter, self).format(record)\n",
      "  File \"c:\\Users\\user\\anaconda3\\lib\\logging\\__init__.py\", line 671, in format\n",
      "    record.exc_text = self.formatException(record.exc_info)\n",
      "  File \"c:\\Users\\user\\anaconda3\\lib\\logging\\__init__.py\", line 621, in formatException\n",
      "    traceback.print_exception(ei[0], ei[1], tb, None, sio)\n",
      "  File \"c:\\Users\\user\\anaconda3\\lib\\traceback.py\", line 103, in print_exception\n",
      "    for line in TracebackException(\n",
      "  File \"c:\\Users\\user\\anaconda3\\lib\\traceback.py\", line 495, in __init__\n",
      "    context = TracebackException(\n",
      "  File \"c:\\Users\\user\\anaconda3\\lib\\traceback.py\", line 495, in __init__\n",
      "    context = TracebackException(\n",
      "  File \"c:\\Users\\user\\anaconda3\\lib\\traceback.py\", line 495, in __init__\n",
      "    context = TracebackException(\n",
      "  [Previous line repeated 5 more times]\n",
      "  File \"c:\\Users\\user\\anaconda3\\lib\\traceback.py\", line 486, in __init__\n",
      "    exc_value.__cause__.__traceback__,\n",
      "AttributeError: 'str' object has no attribute '__traceback__'\n",
      "\n",
      "During handling of the above exception, another exception occurred:\n",
      "\n",
      "Traceback (most recent call last):\n",
      "  File \"c:\\Users\\user\\anaconda3\\lib\\site-packages\\tornado\\ioloop.py\", line 741, in _run_callback\n",
      "    ret = callback()\n",
      "  File \"c:\\Users\\user\\anaconda3\\lib\\site-packages\\tornado\\ioloop.py\", line 765, in _discard_future_result\n",
      "    future.result()\n",
      "  File \"c:\\Users\\user\\anaconda3\\lib\\site-packages\\ipykernel\\kernelbase.py\", line 512, in dispatch_queue\n",
      "    self.log.exception(\"Error in message handler\")\n",
      "  File \"c:\\Users\\user\\anaconda3\\lib\\logging\\__init__.py\", line 1481, in exception\n",
      "    self.error(msg, *args, exc_info=exc_info, **kwargs)\n",
      "  File \"c:\\Users\\user\\anaconda3\\lib\\logging\\__init__.py\", line 1475, in error\n",
      "    self._log(ERROR, msg, args, **kwargs)\n",
      "  File \"c:\\Users\\user\\anaconda3\\lib\\logging\\__init__.py\", line 1589, in _log\n",
      "    self.handle(record)\n",
      "  File \"c:\\Users\\user\\anaconda3\\lib\\logging\\__init__.py\", line 1599, in handle\n",
      "    self.callHandlers(record)\n",
      "  File \"c:\\Users\\user\\anaconda3\\lib\\logging\\__init__.py\", line 1661, in callHandlers\n",
      "    hdlr.handle(record)\n",
      "  File \"c:\\Users\\user\\anaconda3\\lib\\logging\\__init__.py\", line 952, in handle\n",
      "    self.emit(record)\n",
      "  File \"c:\\Users\\user\\anaconda3\\lib\\logging\\__init__.py\", line 1091, in emit\n",
      "    self.handleError(record)\n",
      "  File \"c:\\Users\\user\\anaconda3\\lib\\logging\\__init__.py\", line 1005, in handleError\n",
      "    traceback.print_exception(t, v, tb, None, sys.stderr)\n",
      "  File \"c:\\Users\\user\\anaconda3\\lib\\traceback.py\", line 103, in print_exception\n",
      "    for line in TracebackException(\n",
      "  File \"c:\\Users\\user\\anaconda3\\lib\\traceback.py\", line 495, in __init__\n",
      "    context = TracebackException(\n",
      "  File \"c:\\Users\\user\\anaconda3\\lib\\traceback.py\", line 495, in __init__\n",
      "    context = TracebackException(\n",
      "  File \"c:\\Users\\user\\anaconda3\\lib\\traceback.py\", line 495, in __init__\n",
      "    context = TracebackException(\n",
      "  [Previous line repeated 6 more times]\n",
      "  File \"c:\\Users\\user\\anaconda3\\lib\\traceback.py\", line 486, in __init__\n",
      "    exc_value.__cause__.__traceback__,\n",
      "AttributeError: 'str' object has no attribute '__traceback__'\n",
      "\n",
      "During handling of the above exception, another exception occurred:\n",
      "\n",
      "Traceback (most recent call last):\n",
      "  File \"c:\\Users\\user\\anaconda3\\lib\\logging\\__init__.py\", line 1083, in emit\n",
      "    msg = self.format(record)\n",
      "  File \"c:\\Users\\user\\anaconda3\\lib\\logging\\__init__.py\", line 927, in format\n",
      "    return fmt.format(record)\n",
      "  File \"c:\\Users\\user\\anaconda3\\lib\\logging\\__init__.py\", line 671, in format\n",
      "    record.exc_text = self.formatException(record.exc_info)\n",
      "  File \"c:\\Users\\user\\anaconda3\\lib\\logging\\__init__.py\", line 621, in formatException\n",
      "    traceback.print_exception(ei[0], ei[1], tb, None, sio)\n",
      "  File \"c:\\Users\\user\\anaconda3\\lib\\traceback.py\", line 103, in print_exception\n",
      "    for line in TracebackException(\n",
      "  File \"c:\\Users\\user\\anaconda3\\lib\\traceback.py\", line 495, in __init__\n",
      "    context = TracebackException(\n",
      "  File \"c:\\Users\\user\\anaconda3\\lib\\traceback.py\", line 495, in __init__\n",
      "    context = TracebackException(\n",
      "  File \"c:\\Users\\user\\anaconda3\\lib\\traceback.py\", line 495, in __init__\n",
      "    context = TracebackException(\n",
      "  [Previous line repeated 7 more times]\n",
      "  File \"c:\\Users\\user\\anaconda3\\lib\\traceback.py\", line 486, in __init__\n",
      "    exc_value.__cause__.__traceback__,\n",
      "AttributeError: 'str' object has no attribute '__traceback__'\n",
      "\n",
      "During handling of the above exception, another exception occurred:\n",
      "\n",
      "Traceback (most recent call last):\n",
      "  File \"c:\\Users\\user\\anaconda3\\lib\\asyncio\\events.py\", line 80, in _run\n",
      "    self._context.run(self._callback, *self._args)\n",
      "  File \"c:\\Users\\user\\anaconda3\\lib\\site-packages\\tornado\\ioloop.py\", line 688, in <lambda>\n",
      "    lambda f: self._run_callback(functools.partial(callback, future))\n",
      "  File \"c:\\Users\\user\\anaconda3\\lib\\site-packages\\tornado\\ioloop.py\", line 761, in _run_callback\n",
      "    app_log.error(\"Exception in callback %r\", callback, exc_info=True)\n",
      "  File \"c:\\Users\\user\\anaconda3\\lib\\logging\\__init__.py\", line 1475, in error\n",
      "    self._log(ERROR, msg, args, **kwargs)\n",
      "  File \"c:\\Users\\user\\anaconda3\\lib\\logging\\__init__.py\", line 1589, in _log\n",
      "    self.handle(record)\n",
      "  File \"c:\\Users\\user\\anaconda3\\lib\\logging\\__init__.py\", line 1599, in handle\n",
      "    self.callHandlers(record)\n",
      "  File \"c:\\Users\\user\\anaconda3\\lib\\logging\\__init__.py\", line 1661, in callHandlers\n",
      "    hdlr.handle(record)\n",
      "  File \"c:\\Users\\user\\anaconda3\\lib\\logging\\__init__.py\", line 952, in handle\n",
      "    self.emit(record)\n",
      "  File \"c:\\Users\\user\\anaconda3\\lib\\logging\\__init__.py\", line 1091, in emit\n",
      "    self.handleError(record)\n",
      "  File \"c:\\Users\\user\\anaconda3\\lib\\logging\\__init__.py\", line 1005, in handleError\n",
      "    traceback.print_exception(t, v, tb, None, sys.stderr)\n",
      "  File \"c:\\Users\\user\\anaconda3\\lib\\traceback.py\", line 103, in print_exception\n",
      "    for line in TracebackException(\n",
      "  File \"c:\\Users\\user\\anaconda3\\lib\\traceback.py\", line 495, in __init__\n",
      "    context = TracebackException(\n",
      "  File \"c:\\Users\\user\\anaconda3\\lib\\traceback.py\", line 495, in __init__\n",
      "    context = TracebackException(\n",
      "  File \"c:\\Users\\user\\anaconda3\\lib\\traceback.py\", line 495, in __init__\n",
      "    context = TracebackException(\n",
      "  [Previous line repeated 8 more times]\n",
      "  File \"c:\\Users\\user\\anaconda3\\lib\\traceback.py\", line 486, in __init__\n",
      "    exc_value.__cause__.__traceback__,\n",
      "AttributeError: 'str' object has no attribute '__traceback__'\n",
      "\n",
      "During handling of the above exception, another exception occurred:\n",
      "\n",
      "Traceback (most recent call last):\n",
      "  File \"c:\\Users\\user\\anaconda3\\lib\\logging\\__init__.py\", line 1083, in emit\n",
      "    msg = self.format(record)\n",
      "  File \"c:\\Users\\user\\anaconda3\\lib\\logging\\__init__.py\", line 927, in format\n",
      "    return fmt.format(record)\n",
      "  File \"c:\\Users\\user\\anaconda3\\lib\\logging\\__init__.py\", line 671, in format\n",
      "    record.exc_text = self.formatException(record.exc_info)\n",
      "  File \"c:\\Users\\user\\anaconda3\\lib\\logging\\__init__.py\", line 621, in formatException\n",
      "    traceback.print_exception(ei[0], ei[1], tb, None, sio)\n",
      "  File \"c:\\Users\\user\\anaconda3\\lib\\traceback.py\", line 103, in print_exception\n",
      "    for line in TracebackException(\n",
      "  File \"c:\\Users\\user\\anaconda3\\lib\\traceback.py\", line 495, in __init__\n",
      "    context = TracebackException(\n",
      "  File \"c:\\Users\\user\\anaconda3\\lib\\traceback.py\", line 495, in __init__\n",
      "    context = TracebackException(\n",
      "  File \"c:\\Users\\user\\anaconda3\\lib\\traceback.py\", line 495, in __init__\n",
      "    context = TracebackException(\n",
      "  [Previous line repeated 9 more times]\n",
      "  File \"c:\\Users\\user\\anaconda3\\lib\\traceback.py\", line 486, in __init__\n",
      "    exc_value.__cause__.__traceback__,\n",
      "AttributeError: 'str' object has no attribute '__traceback__'\n",
      "\n",
      "During handling of the above exception, another exception occurred:\n",
      "\n",
      "Traceback (most recent call last):\n",
      "  File \"c:\\Users\\user\\anaconda3\\lib\\asyncio\\base_events.py\", line 1779, in call_exception_handler\n",
      "    self.default_exception_handler(context)\n",
      "  File \"c:\\Users\\user\\anaconda3\\lib\\asyncio\\base_events.py\", line 1753, in default_exception_handler\n",
      "    logger.error('\\n'.join(log_lines), exc_info=exc_info)\n",
      "  File \"c:\\Users\\user\\anaconda3\\lib\\logging\\__init__.py\", line 1475, in error\n",
      "    self._log(ERROR, msg, args, **kwargs)\n",
      "  File \"c:\\Users\\user\\anaconda3\\lib\\logging\\__init__.py\", line 1589, in _log\n",
      "    self.handle(record)\n",
      "  File \"c:\\Users\\user\\anaconda3\\lib\\logging\\__init__.py\", line 1599, in handle\n",
      "    self.callHandlers(record)\n",
      "  File \"c:\\Users\\user\\anaconda3\\lib\\logging\\__init__.py\", line 1669, in callHandlers\n",
      "    lastResort.handle(record)\n",
      "  File \"c:\\Users\\user\\anaconda3\\lib\\logging\\__init__.py\", line 952, in handle\n",
      "    self.emit(record)\n",
      "  File \"c:\\Users\\user\\anaconda3\\lib\\logging\\__init__.py\", line 1091, in emit\n",
      "    self.handleError(record)\n",
      "  File \"c:\\Users\\user\\anaconda3\\lib\\logging\\__init__.py\", line 1005, in handleError\n",
      "    traceback.print_exception(t, v, tb, None, sys.stderr)\n",
      "  File \"c:\\Users\\user\\anaconda3\\lib\\traceback.py\", line 103, in print_exception\n",
      "    for line in TracebackException(\n",
      "  File \"c:\\Users\\user\\anaconda3\\lib\\traceback.py\", line 495, in __init__\n",
      "    context = TracebackException(\n",
      "  File \"c:\\Users\\user\\anaconda3\\lib\\traceback.py\", line 495, in __init__\n",
      "    context = TracebackException(\n",
      "  File \"c:\\Users\\user\\anaconda3\\lib\\traceback.py\", line 495, in __init__\n",
      "    context = TracebackException(\n",
      "  [Previous line repeated 10 more times]\n",
      "  File \"c:\\Users\\user\\anaconda3\\lib\\traceback.py\", line 486, in __init__\n",
      "    exc_value.__cause__.__traceback__,\n",
      "AttributeError: 'str' object has no attribute '__traceback__'\n",
      "\n",
      "During handling of the above exception, another exception occurred:\n",
      "\n",
      "Traceback (most recent call last):\n",
      "  File \"c:\\Users\\user\\anaconda3\\lib\\logging\\__init__.py\", line 1083, in emit\n",
      "    msg = self.format(record)\n",
      "  File \"c:\\Users\\user\\anaconda3\\lib\\logging\\__init__.py\", line 927, in format\n",
      "    return fmt.format(record)\n",
      "  File \"c:\\Users\\user\\anaconda3\\lib\\logging\\__init__.py\", line 671, in format\n",
      "    record.exc_text = self.formatException(record.exc_info)\n",
      "  File \"c:\\Users\\user\\anaconda3\\lib\\logging\\__init__.py\", line 621, in formatException\n",
      "    traceback.print_exception(ei[0], ei[1], tb, None, sio)\n",
      "  File \"c:\\Users\\user\\anaconda3\\lib\\traceback.py\", line 103, in print_exception\n",
      "    for line in TracebackException(\n",
      "  File \"c:\\Users\\user\\anaconda3\\lib\\traceback.py\", line 495, in __init__\n",
      "    context = TracebackException(\n",
      "  File \"c:\\Users\\user\\anaconda3\\lib\\traceback.py\", line 495, in __init__\n",
      "    context = TracebackException(\n",
      "  File \"c:\\Users\\user\\anaconda3\\lib\\traceback.py\", line 495, in __init__\n",
      "    context = TracebackException(\n",
      "  [Previous line repeated 11 more times]\n",
      "  File \"c:\\Users\\user\\anaconda3\\lib\\traceback.py\", line 486, in __init__\n",
      "    exc_value.__cause__.__traceback__,\n",
      "AttributeError: 'str' object has no attribute '__traceback__'\n",
      "\n",
      "During handling of the above exception, another exception occurred:\n",
      "\n",
      "Traceback (most recent call last):\n",
      "  File \"c:\\Users\\user\\anaconda3\\lib\\runpy.py\", line 197, in _run_module_as_main\n",
      "    return _run_code(code, main_globals, None,\n",
      "  File \"c:\\Users\\user\\anaconda3\\lib\\runpy.py\", line 87, in _run_code\n",
      "    exec(code, run_globals)\n",
      "  File \"c:\\Users\\user\\anaconda3\\lib\\site-packages\\ipykernel_launcher.py\", line 17, in <module>\n",
      "    app.launch_new_instance()\n",
      "  File \"c:\\Users\\user\\anaconda3\\lib\\site-packages\\traitlets\\config\\application.py\", line 846, in launch_instance\n",
      "    app.start()\n",
      "  File \"c:\\Users\\user\\anaconda3\\lib\\site-packages\\ipykernel\\kernelapp.py\", line 712, in start\n",
      "    self.io_loop.start()\n",
      "  File \"c:\\Users\\user\\anaconda3\\lib\\site-packages\\tornado\\platform\\asyncio.py\", line 199, in start\n",
      "    self.asyncio_loop.run_forever()\n",
      "  File \"c:\\Users\\user\\anaconda3\\lib\\asyncio\\base_events.py\", line 601, in run_forever\n",
      "    self._run_once()\n",
      "  File \"c:\\Users\\user\\anaconda3\\lib\\asyncio\\base_events.py\", line 1905, in _run_once\n",
      "    handle._run()\n",
      "  File \"c:\\Users\\user\\anaconda3\\lib\\asyncio\\events.py\", line 94, in _run\n",
      "    self._loop.call_exception_handler(context)\n",
      "  File \"c:\\Users\\user\\anaconda3\\lib\\asyncio\\base_events.py\", line 1786, in call_exception_handler\n",
      "    logger.error('Exception in default exception handler',\n",
      "  File \"c:\\Users\\user\\anaconda3\\lib\\logging\\__init__.py\", line 1475, in error\n",
      "    self._log(ERROR, msg, args, **kwargs)\n",
      "  File \"c:\\Users\\user\\anaconda3\\lib\\logging\\__init__.py\", line 1589, in _log\n",
      "    self.handle(record)\n",
      "  File \"c:\\Users\\user\\anaconda3\\lib\\logging\\__init__.py\", line 1599, in handle\n",
      "    self.callHandlers(record)\n",
      "  File \"c:\\Users\\user\\anaconda3\\lib\\logging\\__init__.py\", line 1669, in callHandlers\n",
      "    lastResort.handle(record)\n",
      "  File \"c:\\Users\\user\\anaconda3\\lib\\logging\\__init__.py\", line 952, in handle\n",
      "    self.emit(record)\n",
      "  File \"c:\\Users\\user\\anaconda3\\lib\\logging\\__init__.py\", line 1091, in emit\n",
      "    self.handleError(record)\n",
      "  File \"c:\\Users\\user\\anaconda3\\lib\\logging\\__init__.py\", line 1005, in handleError\n",
      "    traceback.print_exception(t, v, tb, None, sys.stderr)\n",
      "  File \"c:\\Users\\user\\anaconda3\\lib\\traceback.py\", line 103, in print_exception\n",
      "    for line in TracebackException(\n",
      "  File \"c:\\Users\\user\\anaconda3\\lib\\traceback.py\", line 495, in __init__\n",
      "    context = TracebackException(\n",
      "  File \"c:\\Users\\user\\anaconda3\\lib\\traceback.py\", line 495, in __init__\n",
      "    context = TracebackException(\n",
      "  File \"c:\\Users\\user\\anaconda3\\lib\\traceback.py\", line 495, in __init__\n",
      "    context = TracebackException(\n",
      "  [Previous line repeated 12 more times]\n",
      "  File \"c:\\Users\\user\\anaconda3\\lib\\traceback.py\", line 486, in __init__\n",
      "    exc_value.__cause__.__traceback__,\n",
      "AttributeError: 'str' object has no attribute '__traceback__'\n"
     ]
    },
    {
     "ename": "",
     "evalue": "",
     "output_type": "error",
     "traceback": [
      "\u001b[1;31mCanceled future for execute_request message before replies were done"
     ]
    },
    {
     "ename": "",
     "evalue": "",
     "output_type": "error",
     "traceback": [
      "\u001b[1;31m현재 셀 또는 이전 셀에서 코드를 실행하는 동안 Kernel이 충돌했습니다. 셀의 코드를 검토하여 오류의 가능한 원인을 식별하세요. 자세한 내용을 보려면 <a href='https://aka.ms/vscodeJupyterKernelCrash'> 여기 </a> 를 클릭하세요. 자세한 내용은 Jupyter <a href='command:jupyter.viewOutput'>로그</a>를 참조하세요."
     ]
    }
   ],
   "source": [
    "for_apply(\"맛있는김치찌개\")"
   ]
  },
  {
   "cell_type": "code",
   "execution_count": 14,
   "metadata": {},
   "outputs": [
    {
     "data": {
      "text/plain": [
       "array([''], dtype=object)"
      ]
     },
     "execution_count": 14,
     "metadata": {},
     "output_type": "execute_result"
    }
   ],
   "source": [
    "df[\"상품명\"].apply(for_apply)"
   ]
  },
  {
   "cell_type": "markdown",
   "metadata": {},
   "source": [
    "### 고유명사 구축"
   ]
  },
  {
   "cell_type": "code",
   "execution_count": 18,
   "metadata": {},
   "outputs": [],
   "source": [
    "sido = pd.read_csv(r\"C:\\Users\\user\\Desktop\\workbench\\dataset\\국토교통부_전국 법정동_20221031.csv\", encoding= 'cp949')"
   ]
  },
  {
   "cell_type": "code",
   "execution_count": 19,
   "metadata": {},
   "outputs": [],
   "source": [
    "world = pd.read_csv(r\"C:\\Users\\user\\Desktop\\workbench\\dataset\\외교부_국가(지역)별 일반현황_20220629.csv\", encoding= 'cp949')"
   ]
  },
  {
   "cell_type": "code",
   "execution_count": 20,
   "metadata": {},
   "outputs": [],
   "source": [
    "df_list = df[df[\"상점명\"].str.contains(\"_\")][\"상점명\"].str.split(\"_\").str.get(0).unique().tolist() # 테스트 기업 명"
   ]
  },
  {
   "cell_type": "code",
   "execution_count": 21,
   "metadata": {},
   "outputs": [],
   "source": [
    "train_list = train[train[\"상점명\"].str.contains(\"_\")][\"상점명\"].str.split(\"_\").str.get(0).unique().tolist()"
   ]
  },
  {
   "cell_type": "code",
   "execution_count": 22,
   "metadata": {},
   "outputs": [],
   "source": [
    "sigungu_list = sido[\"시군구명\"].str[:-1].unique().tolist()"
   ]
  },
  {
   "cell_type": "code",
   "execution_count": 23,
   "metadata": {},
   "outputs": [],
   "source": [
    "myundong_list = sido[\"시도명\"].str[:2].unique().tolist()"
   ]
  },
  {
   "cell_type": "code",
   "execution_count": 24,
   "metadata": {},
   "outputs": [],
   "source": [
    "world_list = world[\"한글 국가명\"].tolist()"
   ]
  },
  {
   "cell_type": "code",
   "execution_count": 25,
   "metadata": {},
   "outputs": [],
   "source": [
    "nnp_list = world_list + myundong_list + sigungu_list + train_list + df_list"
   ]
  },
  {
   "cell_type": "code",
   "execution_count": 27,
   "metadata": {},
   "outputs": [
    {
     "data": {
      "text/plain": [
       "894"
      ]
     },
     "execution_count": 27,
     "metadata": {},
     "output_type": "execute_result"
    }
   ],
   "source": [
    "len(nnp_list)"
   ]
  },
  {
   "cell_type": "code",
   "execution_count": 28,
   "metadata": {},
   "outputs": [],
   "source": [
    "with open(\"nnp_list.pkl\", \"wb\") as f :\n",
    "    pickle.dump(nnp_list, f)"
   ]
  },
  {
   "cell_type": "code",
   "execution_count": 40,
   "metadata": {},
   "outputs": [
    {
     "data": {
      "text/plain": [
       "894"
      ]
     },
     "execution_count": 40,
     "metadata": {},
     "output_type": "execute_result"
    }
   ],
   "source": [
    "len(nnp_list)"
   ]
  },
  {
   "cell_type": "markdown",
   "metadata": {},
   "source": [
    "### 괄호 데이터 처리 로직 구현"
   ]
  },
  {
   "cell_type": "code",
   "execution_count": 101,
   "metadata": {},
   "outputs": [],
   "source": [
    "def bascket_remove(text) :\n",
    "    pat = re.compile(r\"\\([^)]*\\)|\\[[^)]*\\]\")\n",
    "    pat2 = re.compile(r'\\(|\\)|\\[|\\]')\n",
    "    # result = re.sub(pat2, '', text)]\n",
    "    bascket_find = re.findall(pat, text)\n",
    "    res = [pat2.sub(\"\",i) for i in bascket_find ]\n",
    "    for i in res :\n",
    "        try : \n",
    "            if nnp_list[nnp_list.index(i)] : \n",
    "                pattern = re.compile(f\"\\({i}\\)|\\[{i}\\]\")\n",
    "                delete = pattern.sub(\"\", text)     \n",
    "        except :\n",
    "            if i in algo.option_list :\n",
    "                pattern = re.compile(f\"\\({i}\\)|\\[{i}\\]\")\n",
    "                delete = pattern.sub(\"\", delete)\n",
    "    return delete\n"
   ]
  },
  {
   "cell_type": "code",
   "execution_count": 102,
   "metadata": {},
   "outputs": [
    {
     "data": {
      "text/plain": [
       "'녹차라떼ice'"
      ]
     },
     "execution_count": 102,
     "metadata": {},
     "output_type": "execute_result"
    }
   ],
   "source": [
    "bascket_remove(\"[커피에반하다]녹차라떼ice(tall)\")"
   ]
  },
  {
   "cell_type": "code",
   "execution_count": 31,
   "metadata": {},
   "outputs": [
    {
     "data": {
      "text/plain": [
       "'커피에반하다'"
      ]
     },
     "execution_count": 31,
     "metadata": {},
     "output_type": "execute_result"
    }
   ],
   "source": [
    "nnp_list[nnp_list.index(\"커피에반하다\")]"
   ]
  },
  {
   "cell_type": "code",
   "execution_count": 40,
   "metadata": {},
   "outputs": [],
   "source": [
    "def bascket_remove(text:str) :\n",
    "    \"\"\"_summary_\n",
    "\n",
    "    Args:\n",
    "        text (str): _description_\n",
    "\n",
    "    Returns:\n",
    "        str: _description_\n",
    "    \"\"\"\n",
    "    pat = re.compile(r\"\\([^)]*\\)|\\[[^)]*\\]\")\n",
    "    pat2 = re.compile(r'\\(|\\)|\\[|\\]')\n",
    "    bascket_find = re.findall(pat, text)\n",
    "    print(bascket_find)\n",
    "    if bascket_find : \n",
    "        res = [pat2.sub(\"\",i) for i in bascket_find ]\n",
    "        print(res)\n",
    "        for i in res :\n",
    "            try : #  있는 경우 고유명사 검사\n",
    "                print(\"??\")\n",
    "                if nnp_list[nnp_list.index(i)] : \n",
    "                    print(\"if 안\")\n",
    "                    pattern = re.compile(f\"\\({i}\\)|\\[{i}\\]\")\n",
    "                    sub_result = pattern.sub(\"\", text)  \n",
    "                return \"\".join(sub_result)   \n",
    "            except : # 없는 경우 옵션 검사\n",
    "                print(\"except\")\n",
    "                if i in algo.option_list :\n",
    "                    pattern = re.compile(f\"\\({i}\\)|\\[{i}\\]\")\n",
    "                    except_sub_result = pattern.sub(\"\", text)\n",
    "                if except_sub_result :\n",
    "                    return \"\".join(except_sub_result)\n",
    "    return text"
   ]
  },
  {
   "cell_type": "code",
   "execution_count": 41,
   "metadata": {},
   "outputs": [
    {
     "name": "stdout",
     "output_type": "stream",
     "text": [
      "[]\n"
     ]
    },
    {
     "data": {
      "text/plain": [
       "'아메리카노1L'"
      ]
     },
     "execution_count": 41,
     "metadata": {},
     "output_type": "execute_result"
    }
   ],
   "source": [
    "bascket_remove(\"아메리카노1L\")"
   ]
  },
  {
   "cell_type": "code",
   "execution_count": null,
   "metadata": {},
   "outputs": [],
   "source": []
  }
 ],
 "metadata": {
  "kernelspec": {
   "display_name": "base",
   "language": "python",
   "name": "python3"
  },
  "language_info": {
   "codemirror_mode": {
    "name": "ipython",
    "version": 3
   },
   "file_extension": ".py",
   "mimetype": "text/x-python",
   "name": "python",
   "nbconvert_exporter": "python",
   "pygments_lexer": "ipython3",
   "version": "3.9.13"
  },
  "orig_nbformat": 4,
  "vscode": {
   "interpreter": {
    "hash": "a077222d77dfe082b8f1dd562ad70e458ac2ab76993a0b248ab0476e32e9e8dd"
   }
  }
 },
 "nbformat": 4,
 "nbformat_minor": 2
}
